[I 200227 19:57:38 main:37] Test process initiated!
[I 200227 19:57:38 main:38] Namespace()
[I 200227 19:57:38 main:40] info check!
[W 200227 19:57:38 main:41] warn check!
[E 200227 19:57:38 main:42] error check!
[I 200227 19:57:38 prv_list_search:19] Initiated prv_list_search..
[I 200227 19:57:53 prv_list_search:33] Executing test_login..
[I 200227 19:58:15 prv_list_search:58] Login test executed!!
[I 200227 19:58:16 prv_list_search:19] Initiated prv_list_search..
[I 200227 19:58:26 prv_list_search:66] Executing test_prv_list_search..
[I 200227 19:59:05 prv_list_search:110] Provider List and search test executed!
[I 200227 19:59:05 api_test_1:22] Initiated api_test_1..
[I 200227 19:59:05 api_test_1:26] Reading test data..
[I 200227 19:59:05 api_test_1:31] Executing test_iexchange_cache_init..
[E 200227 19:59:29 api_test_1:47] Error in test_iexchange_cache_init
[E 200227 19:59:29 api_test_1:48] HTTPConnectionPool(host='192.168.2.145', port=94): Max retries exceeded with url: /api/IExchange/IExchangeApiCallCacheInit (Caused by NewConnectionError('<urllib3.connection.HTTPConnection object at 0x00000170CFC42208>: Failed to establish a new connection: [WinError 10060] A connection attempt failed because the connected party did not properly respond after a period of time, or established connection failed because connected host has failed to respond'))
    Traceback (most recent call last):
      File "C:\Users\HP\AppData\Local\Programs\Python\Python37\lib\site-packages\urllib3\connection.py", line 171, in _new_conn
        (self._dns_host, self.port), self.timeout, **extra_kw)
      File "C:\Users\HP\AppData\Local\Programs\Python\Python37\lib\site-packages\urllib3\util\connection.py", line 79, in create_connection
        raise err
      File "C:\Users\HP\AppData\Local\Programs\Python\Python37\lib\site-packages\urllib3\util\connection.py", line 69, in create_connection
        sock.connect(sa)
    TimeoutError: [WinError 10060] A connection attempt failed because the connected party did not properly respond after a period of time, or established connection failed because connected host has failed to respond
    
    During handling of the above exception, another exception occurred:
    
    Traceback (most recent call last):
      File "C:\Users\HP\AppData\Local\Programs\Python\Python37\lib\site-packages\urllib3\connectionpool.py", line 600, in urlopen
        chunked=chunked)
      File "C:\Users\HP\AppData\Local\Programs\Python\Python37\lib\site-packages\urllib3\connectionpool.py", line 354, in _make_request
        conn.request(method, url, **httplib_request_kw)
      File "C:\Users\HP\AppData\Local\Programs\Python\Python37\lib\http\client.py", line 1229, in request
        self._send_request(method, url, body, headers, encode_chunked)
      File "C:\Users\HP\AppData\Local\Programs\Python\Python37\lib\http\client.py", line 1275, in _send_request
        self.endheaders(body, encode_chunked=encode_chunked)
      File "C:\Users\HP\AppData\Local\Programs\Python\Python37\lib\http\client.py", line 1224, in endheaders
        self._send_output(message_body, encode_chunked=encode_chunked)
      File "C:\Users\HP\AppData\Local\Programs\Python\Python37\lib\http\client.py", line 1016, in _send_output
        self.send(msg)
      File "C:\Users\HP\AppData\Local\Programs\Python\Python37\lib\http\client.py", line 956, in send
        self.connect()
      File "C:\Users\HP\AppData\Local\Programs\Python\Python37\lib\site-packages\urllib3\connection.py", line 196, in connect
        conn = self._new_conn()
      File "C:\Users\HP\AppData\Local\Programs\Python\Python37\lib\site-packages\urllib3\connection.py", line 180, in _new_conn
        self, "Failed to establish a new connection: %s" % e)
    urllib3.exceptions.NewConnectionError: <urllib3.connection.HTTPConnection object at 0x00000170CFC42208>: Failed to establish a new connection: [WinError 10060] A connection attempt failed because the connected party did not properly respond after a period of time, or established connection failed because connected host has failed to respond
    
    During handling of the above exception, another exception occurred:
    
    Traceback (most recent call last):
      File "C:\Users\HP\AppData\Local\Programs\Python\Python37\lib\site-packages\requests\adapters.py", line 445, in send
        timeout=timeout
      File "C:\Users\HP\AppData\Local\Programs\Python\Python37\lib\site-packages\urllib3\connectionpool.py", line 638, in urlopen
        _stacktrace=sys.exc_info()[2])
      File "C:\Users\HP\AppData\Local\Programs\Python\Python37\lib\site-packages\urllib3\util\retry.py", line 398, in increment
        raise MaxRetryError(_pool, url, error or ResponseError(cause))
    urllib3.exceptions.MaxRetryError: HTTPConnectionPool(host='192.168.2.145', port=94): Max retries exceeded with url: /api/IExchange/IExchangeApiCallCacheInit (Caused by NewConnectionError('<urllib3.connection.HTTPConnection object at 0x00000170CFC42208>: Failed to establish a new connection: [WinError 10060] A connection attempt failed because the connected party did not properly respond after a period of time, or established connection failed because connected host has failed to respond'))
    
    During handling of the above exception, another exception occurred:
    
    Traceback (most recent call last):
      File "D:\Santech\BitBucket\Automation\PySelenium\api_test_1.py", line 39, in test_iexchange_cache_init
        response = requests.post(url)
      File "C:\Users\HP\AppData\Local\Programs\Python\Python37\lib\site-packages\requests\api.py", line 112, in post
        return request('post', url, data=data, json=json, **kwargs)
      File "C:\Users\HP\AppData\Local\Programs\Python\Python37\lib\site-packages\requests\api.py", line 58, in request
        return session.request(method=method, url=url, **kwargs)
      File "C:\Users\HP\AppData\Local\Programs\Python\Python37\lib\site-packages\requests\sessions.py", line 512, in request
        resp = self.send(prep, **send_kwargs)
      File "C:\Users\HP\AppData\Local\Programs\Python\Python37\lib\site-packages\requests\sessions.py", line 622, in send
        r = adapter.send(request, **kwargs)
      File "C:\Users\HP\AppData\Local\Programs\Python\Python37\lib\site-packages\requests\adapters.py", line 513, in send
        raise ConnectionError(e, request=request)
    requests.exceptions.ConnectionError: HTTPConnectionPool(host='192.168.2.145', port=94): Max retries exceeded with url: /api/IExchange/IExchangeApiCallCacheInit (Caused by NewConnectionError('<urllib3.connection.HTTPConnection object at 0x00000170CFC42208>: Failed to establish a new connection: [WinError 10060] A connection attempt failed because the connected party did not properly respond after a period of time, or established connection failed because connected host has failed to respond'))
[I 200227 19:59:29 api_test_1:82] api_test_1 test completed!!
[I 200227 19:59:29 api_test_1:22] Initiated api_test_1..
[I 200227 19:59:29 api_test_1:26] Reading test data..
[I 200227 19:59:29 api_test_1:52] Executing test_api..
[E 200227 19:59:50 api_test_1:79] HTTPConnectionPool(host='192.168.2.145', port=94): Max retries exceeded with url: /api/IExchange/IExchangeApiCall (Caused by NewConnectionError('<urllib3.connection.HTTPConnection object at 0x00000170CFC58EB8>: Failed to establish a new connection: [WinError 10060] A connection attempt failed because the connected party did not properly respond after a period of time, or established connection failed because connected host has failed to respond'))
    Traceback (most recent call last):
      File "C:\Users\HP\AppData\Local\Programs\Python\Python37\lib\site-packages\urllib3\connection.py", line 171, in _new_conn
        (self._dns_host, self.port), self.timeout, **extra_kw)
      File "C:\Users\HP\AppData\Local\Programs\Python\Python37\lib\site-packages\urllib3\util\connection.py", line 79, in create_connection
        raise err
      File "C:\Users\HP\AppData\Local\Programs\Python\Python37\lib\site-packages\urllib3\util\connection.py", line 69, in create_connection
        sock.connect(sa)
    TimeoutError: [WinError 10060] A connection attempt failed because the connected party did not properly respond after a period of time, or established connection failed because connected host has failed to respond
    
    During handling of the above exception, another exception occurred:
    
    Traceback (most recent call last):
      File "C:\Users\HP\AppData\Local\Programs\Python\Python37\lib\site-packages\urllib3\connectionpool.py", line 600, in urlopen
        chunked=chunked)
      File "C:\Users\HP\AppData\Local\Programs\Python\Python37\lib\site-packages\urllib3\connectionpool.py", line 354, in _make_request
        conn.request(method, url, **httplib_request_kw)
      File "C:\Users\HP\AppData\Local\Programs\Python\Python37\lib\http\client.py", line 1229, in request
        self._send_request(method, url, body, headers, encode_chunked)
      File "C:\Users\HP\AppData\Local\Programs\Python\Python37\lib\http\client.py", line 1275, in _send_request
        self.endheaders(body, encode_chunked=encode_chunked)
      File "C:\Users\HP\AppData\Local\Programs\Python\Python37\lib\http\client.py", line 1224, in endheaders
        self._send_output(message_body, encode_chunked=encode_chunked)
      File "C:\Users\HP\AppData\Local\Programs\Python\Python37\lib\http\client.py", line 1016, in _send_output
        self.send(msg)
      File "C:\Users\HP\AppData\Local\Programs\Python\Python37\lib\http\client.py", line 956, in send
        self.connect()
      File "C:\Users\HP\AppData\Local\Programs\Python\Python37\lib\site-packages\urllib3\connection.py", line 196, in connect
        conn = self._new_conn()
      File "C:\Users\HP\AppData\Local\Programs\Python\Python37\lib\site-packages\urllib3\connection.py", line 180, in _new_conn
        self, "Failed to establish a new connection: %s" % e)
    urllib3.exceptions.NewConnectionError: <urllib3.connection.HTTPConnection object at 0x00000170CFC58EB8>: Failed to establish a new connection: [WinError 10060] A connection attempt failed because the connected party did not properly respond after a period of time, or established connection failed because connected host has failed to respond
    
    During handling of the above exception, another exception occurred:
    
    Traceback (most recent call last):
      File "C:\Users\HP\AppData\Local\Programs\Python\Python37\lib\site-packages\requests\adapters.py", line 445, in send
        timeout=timeout
      File "C:\Users\HP\AppData\Local\Programs\Python\Python37\lib\site-packages\urllib3\connectionpool.py", line 638, in urlopen
        _stacktrace=sys.exc_info()[2])
      File "C:\Users\HP\AppData\Local\Programs\Python\Python37\lib\site-packages\urllib3\util\retry.py", line 398, in increment
        raise MaxRetryError(_pool, url, error or ResponseError(cause))
    urllib3.exceptions.MaxRetryError: HTTPConnectionPool(host='192.168.2.145', port=94): Max retries exceeded with url: /api/IExchange/IExchangeApiCall (Caused by NewConnectionError('<urllib3.connection.HTTPConnection object at 0x00000170CFC58EB8>: Failed to establish a new connection: [WinError 10060] A connection attempt failed because the connected party did not properly respond after a period of time, or established connection failed because connected host has failed to respond'))
    
    During handling of the above exception, another exception occurred:
    
    Traceback (most recent call last):
      File "D:\Santech\BitBucket\Automation\PySelenium\api_test_1.py", line 69, in test_api
        response = requests.post(api_url, json=data)
      File "C:\Users\HP\AppData\Local\Programs\Python\Python37\lib\site-packages\requests\api.py", line 112, in post
        return request('post', url, data=data, json=json, **kwargs)
      File "C:\Users\HP\AppData\Local\Programs\Python\Python37\lib\site-packages\requests\api.py", line 58, in request
        return session.request(method=method, url=url, **kwargs)
      File "C:\Users\HP\AppData\Local\Programs\Python\Python37\lib\site-packages\requests\sessions.py", line 512, in request
        resp = self.send(prep, **send_kwargs)
      File "C:\Users\HP\AppData\Local\Programs\Python\Python37\lib\site-packages\requests\sessions.py", line 622, in send
        r = adapter.send(request, **kwargs)
      File "C:\Users\HP\AppData\Local\Programs\Python\Python37\lib\site-packages\requests\adapters.py", line 513, in send
        raise ConnectionError(e, request=request)
    requests.exceptions.ConnectionError: HTTPConnectionPool(host='192.168.2.145', port=94): Max retries exceeded with url: /api/IExchange/IExchangeApiCall (Caused by NewConnectionError('<urllib3.connection.HTTPConnection object at 0x00000170CFC58EB8>: Failed to establish a new connection: [WinError 10060] A connection attempt failed because the connected party did not properly respond after a period of time, or established connection failed because connected host has failed to respond'))
[I 200227 19:59:50 api_test_1:82] api_test_1 test completed!!
[I 200227 19:59:50 api_test_2:22] Initiated api_test_2..
[I 200227 19:59:50 api_test_2:25] Executing test_api_2..
[I 200227 19:59:50 api_test_2:30] Reading test data..
